<?xml version="1.0"?>
<robot xmlns:xacro="http://www.ros.org/wiki/xacro">

    <material name="white">
        <color rgba="1 1 1 1"/>
    </material>

    <material name="orange">
        <color rgba="1 0.3 0.1 1"/>
    </material>

    <material name="blue">
        <color rgba="0.2 0.2 1 1"/>
    </material>

    <material name="black">
        <color rgba="0 0 0 1"/>
    </material>

    <link name="base_link">
    </link>

    <!-- Define a link for each wheel -->
    <link name="front_left_wheel_link">
        <visual>
            <geometry>
                <cylinder radius="0.1" length="0.05"/>
            </geometry>
            <material name="black"/>
        </visual>
    </link>

    <link name="front_right_wheel_link">
        <visual>
            <geometry>
                <cylinder radius="0.1" length="0.05"/>
            </geometry>
            <material name="black"/>
        </visual>
    </link>

    <link name="rear_left_wheel_link">
        <visual>
            <geometry>
                <cylinder radius="0.1" length="0.05"/>
            </geometry>
            <material name="black"/>
        </visual>
    </link>

    <link name="rear_right_wheel_link">
        <visual>
            <geometry>
                <cylinder radius="0.1" length="0.05"/>
            </geometry>
            <material name="black"/>
        </visual>
    </link>

    <!-- Joint to connect each wheel to the base link -->
    <!-- Adjust the origin to place the wheel correctly relative to the base_link -->

    <joint name="front_left_wheel_joint" type="continuous">
        <parent link="base_link"/>
        <child link="front_left_wheel_link"/>
        <origin xyz="0.18 0.105 0" rpy="0 0 0"/>
        <axis xyz="0 0 1"/>
    </joint>

    <joint name="front_right_wheel_joint" type="continuous">
        <parent link="base_link"/>
        <child link="front_right_wheel_link"/>
        <origin xyz="0.18 -0.105 0" rpy="0 0 0"/>
        <axis xyz="0 0 1"/>
    </joint>

    <joint name="rear_left_wheel_joint" type="continuous">
        <parent link="base_link"/>
        <child link="rear_left_wheel_link"/>
        <origin xyz="-0.025 0.105 0" rpy="0 0 0"/>
        <axis xyz="0 0 1"/>
    </joint>

    <joint name="rear_right_wheel_joint" type="continuous">
        <parent link="base_link"/>
        <child link="rear_right_wheel_link"/>
        <origin xyz="-0.025 -0.105 0" rpy="0 0 0"/>
        <axis xyz="0 0 1"/>
    </joint>

</robot>

